<?xml version="1.0"?>
<robot xmlns:xacro="http://ros.org/wiki/xacro" name="mobile_robot">

  <material name="black">
    <color rgba="0 0 0 1"/>
  </material>

  <material name="blue">
    <color rgba="0 0 0.8 0.8"/>
  </material>

  <material name="olivegreen">
    <color rgba="0.729 0.722 0.424 1.0"/>
  </material>

  <material name="white">
    <color rgba="1 1 1 1"/>
  </material>

  <link name="base_link">
    <collision>
      <origin rpy="0 0 0" xyz="0 0 0.0005"/>
      <geometry>
        <box size="0.22 0.22 0.001"/>
      </geometry>
    </collision>
  </link>

  <joint name="base_link_joint" type="fixed">
    <origin xyz="0 0 0.026" rpy="0 0 -1.5708" />
    <parent link="base_link" />
    <child link="base_plate" />
  </joint>

  <link name="base_plate">
    <visual>
      <origin rpy="0 0 0" xyz="0.03 0 -0.026"/>
      <geometry>
        <mesh filename="package://rover_ctrl/meshes/Chasis.stl" scale="0.001 0.001 0.001"/>
      </geometry>
      <material name="olivegreen"/>
    </visual>
    <collision>
      <origin rpy="0 0 0" xyz="0.03 0 -0.026" />
      <geometry>
        <mesh filename="package://rover_ctrl/meshes/Chasis.stl" scale="0.001 0.001 0.001" />
      </geometry>
    </collision>
  </link>

  <joint name="laser_joint" type="fixed">
    <origin xyz="0 0.040 0.090" rpy="0 0 1.5708" />
    <parent link="base_plate" />
    <child link="laser" />
  </joint>

  <link name="laser">
    <visual>
      <origin rpy="0 0 -1.5708" xyz="0.084 -0.242 -0.098"/>
      <geometry>
        <mesh filename="package://rover_ctrl/meshes/RpLidar.stl" scale="0.001 0.001 0.001"/>
      </geometry>
      <material name="blue"/>
    </visual>
    <collision>
      <origin rpy="0 0 0" xyz="0.242 0.084 -0.098" />
      <geometry>
        <mesh filename="package://rover_ctrl/meshes/RpLidar.stl" scale="0.001 0.001 0.001" />
      </geometry>
    </collision>
  </link>

  <xacro:macro name="wheel" params="side joint_x x">

    <joint name="${side}_wheel_joint" type="continuous">
      <origin xyz="${joint_x} -0.06 0.015" rpy="0 0 0" />
      <parent link="base_plate" />
      <child link="${side}_wheel" />
      <axis xyz="-1 0 0" />
    </joint>

    <link name="${side}_wheel">
      <visual>
        <origin rpy="0 0 0" xyz="${x} 0.059 -0.04"/>
        <geometry>
          <mesh filename="package://rover_ctrl/meshes/Wheel.stl" scale="0.001 0.001 0.001"/>
        </geometry>
        <material name="black"/>
      </visual>
      <collision>
        <origin rpy="0 0 0" xyz="${x} 0.059 -0.04"/>
        <geometry>
          <mesh filename="package://rover_ctrl/meshes/Wheel.stl" scale="0.001 0.001 0.001" />
        </geometry>
      </collision>
    </link>

  </xacro:macro>

  <xacro:wheel side="left" joint_x="0.08" x="0.133"/>
  <xacro:wheel side="right" joint_x="-0.08" x="0.11"/>

</robot>
